<?xml version='1.0'?>
<robot name="minimal2WD_sonar">

  <!-- Body -->
  <link name="base_link">
    <visual>
      <origin xyz="0 0 0" rpy="0 0 0" />
      <geometry>
          <box size="0.175 0.11 0.055"/>
      </geometry>
      <material name="red">
        <color rgba="1 0 0 1"/>
      </material>
    </visual>
    <!-- Base collision, mass and inertia -->
    <collision>
      <origin xyz="0 0 0" rpy="0 0 0" />
      <geometry>
          <box size="0.175 0.11 0.055"/>
      </geometry>
    </collision>
    <inertial>
      <mass value="1"/>
      <inertia ixx="0.0013" ixy="0.0" ixz="0.0" iyy="0.0028" iyz="0.0" izz="0.0036"/>
    </inertial>

    <!-- Caster -->
    <visual name="caster">
      <origin xyz="-0.0675 0 -0.0275" rpy="0 0 0" />
      <geometry>
        <sphere radius="0.015" />
      </geometry>
    </visual>
    <!-- Caster collision, mass and inertia -->
    <collision>
      <origin xyz="-0.0675 0 -0.0275" rpy="0 0 0" />
      <geometry>
        <sphere radius="0.015" />
      </geometry>
    </collision>
    <inertial>
      <mass value="0.1"/>
      <inertia ixx="0.00001" ixy="0.0" ixz="0.0" iyy="0.00001" iyz="0.0" izz="0.00001"/>
    </inertial>
  </link>

  <!-- Right Wheel -->
  <link name="right_wheel">
    <visual>
      <origin xyz="0 0 0" rpy="1.570795 0 0" />
      <geometry>
          <cylinder length="0.03" radius="0.0325" />
      </geometry>
      <material name="black">
        <color rgba="0.05 0.05 0.05 1"/>
      </material>
    </visual>
    <!-- Right Wheel collision, mass and inertia -->
    <collision>
      <origin xyz="0 0 0" rpy="1.570795 0 0" />
      <geometry>
          <cylinder length="0.03" radius="0.0325" />
      </geometry>
    </collision>
    <inertial>
      <mass value="0.1"/>
      <inertia ixx="0.000034" ixy="0.0" ixz="0.0" iyy="0.000053" iyz="0.0" izz="0.000034"/>
    </inertial>
  </link>

  <!-- Right Wheel joint -->
  <joint name="joint_right_wheel" type="continuous">
    <parent link="base_link"/>
    <child link="right_wheel"/>
    <origin xyz="0.02 -0.07 -0.01" rpy="0 0 0" /> 
    <axis xyz="0 1 0" />
  </joint>

  <!-- Left Wheel -->
  <link name="left_wheel">
    <visual>
      <origin xyz="0 0 0" rpy="1.570795 0 0" />
      <geometry>
          <cylinder length="0.03" radius="0.0325" />
      </geometry>
      <material name="black"/>
    </visual>
    <!-- Left Wheel collision, mass and inertia -->
    <collision>
      <origin xyz="0 0 0" rpy="1.570795 0 0" />
      <geometry>
          <cylinder length="0.03" radius="0.0325" />
      </geometry>
    </collision>
    <inertial>
      <mass value="0.1"/>
      <inertia ixx="0.000034" ixy="0.0" ixz="0.0" iyy="0.000053" iyz="0.0" izz="0.000034"/>
    </inertial>
  </link>

  <!-- Right Wheel joint -->
  <joint name="joint_left_wheel" type="continuous">
    <parent link="base_link"/>
    <child link="left_wheel"/>
    <origin xyz="0.02 0.07 -0.01" rpy="0 0 0" /> 
    <axis xyz="0 1 0" />
  </joint>

  <!-- Right Ultrasound Sensor -->
  <link  name="sonar_solid_r">
   <visual>
     <origin xyz="0 0 0" rpy="0 0 0" />
     <geometry>
       <box size="0.015 0.045 0.020"/>
     </geometry>
     <material name="blue">
       <color rgba="0.0 0.05 1 1"/>
     </material>
   </visual>
   <!-- Sensor collision, mass and inertia -->
     <collision>
       <origin xyz="0 0 0" rpy="0 0 0" />
       <geometry>
         <box size="0.015 0.045 0.020"/>
       </geometry>
     </collision>
     <inertial>
       <mass value="0.009"/>
       <inertia ixx="0.000002" ixy="0.0" ixz="0.0" iyy="0.0000005" iyz="0.0" izz="0.000002"/>
     </inertial>
  </link>

  <link name="sensor_hack_r"/>

  <!-- Sensor joint -->
  <joint name="joint_sonar_solid_r" type="fixed">
    <parent link="base_link" />
    <child link="sonar_solid_r" />
    <origin xyz="0.0575 -0.045 0.0375" rpy="0 0 -0.78" />
  </joint>

  <joint name="joint_fake_r" type="fixed">
    <parent link="sonar_solid_r" />
    <child link="sensor_hack_r" />
    <origin xyz="0.008 0 0" rpy="0 0 0"/>
  </joint>

<!-- Center Ultrasound Sensor -->
  <link  name="sonar_solid">
   <visual>
     <origin xyz="0 0 0" rpy="0 0 0" />
     <geometry>
       <box size="0.015 0.045 0.020"/>
     </geometry>
     <material name="blue">
       <color rgba="0.0 0.05 1 1"/>
     </material>
   </visual>
   <!-- Sensor collision, mass and inertia -->
     <collision>
       <origin xyz="0 0 0" rpy="0 0 0" />
       <geometry>
         <box size="0.015 0.045 0.020"/>
       </geometry>
     </collision>
     <inertial>
       <mass value="0.009"/>
       <inertia ixx="0.000002" ixy="0.0" ixz="0.0" iyy="0.0000005" iyz="0.0" izz="0.000002"/>
     </inertial>
  </link>

  <link name="sensor_hack"/>

  <!-- Sensor joint -->
  <joint name="joint_sonar_solid" type="fixed">
    <parent link="base_link" />
    <child link="sonar_solid" />
    <origin xyz="0.0875 0 0.0375" rpy="0 0 0" />
  </joint>

  <joint name="joint_fake" type="fixed">
    <parent link="sonar_solid" />
    <child link="sensor_hack" />
    <origin xyz="0.008 0 0" rpy="0 0 0"/>
  </joint>

  <!-- Left Ultrasound Sensor -->
  <link  name="sonar_solid_l">
   <visual>
     <origin xyz="0 0 0" rpy="0 0 0" />
     <geometry>
       <box size="0.015 0.045 0.020"/>
     </geometry>
     <material name="blue">
       <color rgba="0.0 0.05 1 1"/>
     </material>
   </visual>
   <!-- Sensor collision, mass and inertia -->
     <collision>
       <origin xyz="0 0 0" rpy="0 0 0" />
       <geometry>
         <box size="0.015 0.045 0.020"/>
       </geometry>
     </collision>
     <inertial>
       <mass value="0.009"/>
       <inertia ixx="0.000002" ixy="0.0" ixz="0.0" iyy="0.0000005" iyz="0.0" izz="0.000002"/>
     </inertial>
  </link>

  <link name="sensor_hack_l"/>

  <!-- Sensor joint -->
  <joint name="joint_sonar_solid_l" type="fixed">
    <parent link="base_link" />
    <child link="sonar_solid_l" />
    <origin xyz="0.0575 0.045 0.0375" rpy="0 0 0.78" />
  </joint>

  <joint name="joint_fake_l" type="fixed">
    <parent link="sonar_solid_l" />
    <child link="sensor_hack_l" />
    <origin xyz="0.008 0 0" rpy="0 0 0"/>
  </joint>

  <!-- Camera -->
  <link  name="camera_link">
   <visual>
     <origin xyz="0.005 0 0" rpy="0 0 0" />
     <geometry>
       <box size="0.01 0.01 0.01"/>
     </geometry>
     <material name="black"/>
   </visual>
   <!-- Camera collision, mass and inertia -->
     <collision>
       <origin xyz="0 0 0" rpy="0 0 0" />
       <geometry>
         <box size="0.02 0.02 0.02"/>
       </geometry>
     </collision>
     <inertial>
       <mass value="0.004"/>
       <inertia ixx="0.0000003" ixy="0.0" ixz="0.0" iyy="0.0000003" iyz="0.0" izz="0.0000003"/>
     </inertial>
  </link>

  <!-- Camera joint -->
  <joint name="joint_camera" type="fixed">
    <parent link="base_link" />
    <child link="camera_link" />
    <origin xyz="0.0875 0 0" rpy="0 0 0" />
  </joint>
  
  <!-- Gazebo specific entries -->
  <gazebo reference="base_link">
    <material>Gazebo/Red</material>
  </gazebo>

  <gazebo reference="caster">
    <material>Gazebo/Red</material>
  </gazebo>

  <gazebo reference="right_wheel">
    <material>Gazebo/Black</material>
  </gazebo>

  <gazebo reference="left_wheel">
    <material>Gazebo/Black</material>
  </gazebo>

  <gazebo reference="sonar_solid">
    <material>Gazebo/Blue</material>
  </gazebo>

  <gazebo reference="sonar_solid_r">
    <material>Gazebo/Blue</material>
  </gazebo>

  <gazebo reference="sonar_solid_l">
    <material>Gazebo/Blue</material>
  </gazebo>


  <gazebo reference="camera_link">
    <material>Gazebo/Black</material>
    <sensor type="camera" name="camera_front">
      <update_rate>30.0</update_rate>
      <camera name="front">
        <horizontal_fov>1.3962634</horizontal_fov>
        <image>
          <width>800</width>
          <height>800</height>
          <format>R8G8B8</format>
        </image>
        <clip>
          <near>0.02</near>
          <far>300</far>
        </clip>
      </camera>
      <plugin name="camera_controller" filename="libgazebo_ros_camera.so">
        <alwaysOn>true</alwaysOn>
        <updateRate>0.0</updateRate>
        <cameraName>sensor/camera_front</cameraName>
        <imageTopicName>image_raw</imageTopicName>
        <cameraInfoTopicName>camera_info</cameraInfoTopicName>
        <frameName>camera_link</frameName>
        <hackBaseline>0.07</hackBaseline>
        <distortionK1>0.0</distortionK1>
        <distortionK2>0.0</distortionK2>
        <distortionK3>0.0</distortionK3>
        <distortionT1>0.0</distortionT1>
        <distortionT2>0.0</distortionT2>
      </plugin>
    </sensor>
  </gazebo>

  <gazebo reference="sensor_hack">        
    <sensor type="ray" name="center_sonar">
      <always_on>1</always_on>
      <visualize>true</visualize>
      <update_rate>5</update_rate>
      <ray>
         <scan>
            <horizontal>
               <samples>50</samples>
               <resolution>1</resolution> 
               <min_angle>-0.175</min_angle>
               <max_angle>0.175</max_angle>
            </horizontal>
            <vertical>
               <samples>50</samples>
               <resolution>1</resolution> 
               <min_angle>-0.175</min_angle>
               <max_angle>0.175</max_angle> 
            </vertical>
         </scan>
         <range>
            <min>0.001</min>
            <max>2</max>
            <resolution>0.0005</resolution>
         </range>
      </ray>
      <plugin filename="libgazebo_ros_range.so" name="gazebo_ros_ir">
         <gaussianNoise>0.005</gaussianNoise>
         <alwaysOn>true</alwaysOn>
         <updateRate>5</updateRate>
         <topicName>sensor/sonar_scan</topicName>
         <frameName>sonar_solid</frameName>
         <radiation>ultrasound</radiation>
         <fov>0.175</fov>
      </plugin>
    </sensor>  
   </gazebo>

  <gazebo reference="sensor_hack_r">        
    <sensor type="ray" name="right_sonar">
      <always_on>1</always_on>
      <visualize>true</visualize>
      <update_rate>5</update_rate>
      <ray>
         <scan>
            <horizontal>
               <samples>50</samples>
               <resolution>1</resolution> 
               <min_angle>-0.175</min_angle>
               <max_angle>0.175</max_angle>
            </horizontal>
            <vertical>
               <samples>50</samples>
               <resolution>1</resolution> 
               <min_angle>-0.175</min_angle>
               <max_angle>0.175</max_angle> 
            </vertical>
         </scan>
         <range>
            <min>0.001</min>
            <max>2</max>
            <resolution>0.0005</resolution>
         </range>
      </ray>
      <plugin filename="libgazebo_ros_range.so" name="gazebo_ros_ir">
         <gaussianNoise>0.005</gaussianNoise>
         <alwaysOn>true</alwaysOn>
         <updateRate>5</updateRate>
         <topicName>sensor/sonar_scan_r</topicName>
         <frameName>sonar_solid_r</frameName>
         <radiation>ultrasound</radiation>
         <fov>0.175</fov>
      </plugin>
    </sensor>  
   </gazebo>

     <gazebo reference="sensor_hack_l">        
    <sensor type="ray" name="left_sonar">
      <always_on>1</always_on>
      <visualize>true</visualize>
      <update_rate>5</update_rate>
      <ray>
         <scan>
            <horizontal>
               <samples>50</samples>
               <resolution>1</resolution> 
               <min_angle>-0.175</min_angle>
               <max_angle>0.175</max_angle>
            </horizontal>
            <vertical>
               <samples>50</samples>
               <resolution>1</resolution> 
               <min_angle>-0.175</min_angle>
               <max_angle>0.175</max_angle> 
            </vertical>
         </scan>
         <range>
            <min>0.001</min>
            <max>2</max>
            <resolution>0.0005</resolution>
         </range>
      </ray>
      <plugin filename="libgazebo_ros_range.so" name="gazebo_ros_ir">
         <gaussianNoise>0.005</gaussianNoise>
         <alwaysOn>true</alwaysOn>
         <updateRate>5</updateRate>
         <topicName>sensor/sonar_scan_l</topicName>
         <frameName>sonar_solid_l</frameName>
         <radiation>ultrasound</radiation>
         <fov>0.175</fov>
      </plugin>
    </sensor>  
   </gazebo>
  <!-- Differential Drive Controller -->
  <gazebo>
    <plugin filename="libgazebo_ros_diff_drive.so" name="differential_drive_controller">
      <alwaysOn>true</alwaysOn>
      <updateRate>20</updateRate>
      <leftJoint>joint_left_wheel</leftJoint>
      <rightJoint>joint_right_wheel</rightJoint>
      <wheelSeparation>0.14</wheelSeparation>
      <wheelDiameter>0.065</wheelDiameter>
      <torque>0.5</torque>
      <commandTopic>/robot/cmd_vel</commandTopic>
      <odometryTopic>odom</odometryTopic>
      <odometryFrame>odom</odometryFrame>
      <robotBaseFrame>base_link</robotBaseFrame>
      <legacyMode>false</legacyMode>
      <publishTf>1</publishTf>
      <rosDebugLevel>na</rosDebugLevel>
      <publishWheelTF>false</publishWheelTF>
      <publishOdomTF>true</publishOdomTF>
      <publishWheelJointState>false</publishWheelJointState>
      <wheelAcceleration>0</wheelAcceleration>
      <wheelTorque>5</wheelTorque>
    </plugin>
  </gazebo>
</robot>
